Workbook
Name nproducto: [1]NPRODUCTOS!$J$9:$U$7009

Sheet CATASTRO Y PLANIFICACIÓN MP
A3: SERVICIO DE SALUD | B3: AYSEN
A5: NOMBRE ESTABLECIMIENTO | B5: Hospiotal Regional Coyhaique
A7: RESPONSABLE TÉCNICO | B7: Raul Aravena Turra | X7: MONITOREO MENSUAL DEL PLAN
X8: % EJECUCIÓN MP TOTAL MENSUAL | Y8: =+'TABLA CÁLCULO'!B24 -> 1 | Z8: =+'TABLA CÁLCULO'!C24 | AA8: =+'TABLA CÁLCULO'!D24 | AB8: =+'TABLA CÁLCULO'!E24 | AC8: =+'TABLA CÁLCULO'!F24 | AD8: =+'TABLA CÁLCULO'!G24 | AE8: =+'TABLA CÁLCULO'!H24 | AF8: =+'TABLA CÁLCULO'!I24 | ... AJ8: =+'TABLA CÁLCULO'!M24
A9: AÑO DE LEVANTAMIENTO | B9: 2026 | X9: % EJECUCIÓN MP EQC MENSUAL | Y9: =+'TABLA CÁLCULO'!B25 -> 1 | Z9: =+'TABLA CÁLCULO'!C25 | AA9: =+'TABLA CÁLCULO'!D25 | AB9: =+'TABLA CÁLCULO'!E25 | AC9: =+'TABLA CÁLCULO'!F25 | AD9: =+'TABLA CÁLCULO'!G25 | AE9: =+'TABLA CÁLCULO'!H25 | AF9: =+'TABLA CÁLCULO'!I25 | ... AJ9: =+'TABLA CÁLCULO'!M25
X10: % EJECUCIÓN MP EQR MENSUAL | Y10: =+'TABLA CÁLCULO'!B26 -> 1 | Z10: =+'TABLA CÁLCULO'!C26 | AA10: =+'TABLA CÁLCULO'!D26 | AB10: =+'TABLA CÁLCULO'!E26 | AC10: =+'TABLA CÁLCULO'!F26 | AD10: =+'TABLA CÁLCULO'!G26 | AE10: =+'TABLA CÁLCULO'!H26 | AF10: =+'TABLA CÁLCULO'!I26 | ... AJ10: =+'TABLA CÁLCULO'!M26
A11: GASTO PROGRAMADO MP | B11: 450000000 | D11: EJECUCIÓN GASTO MP | E11: 97382016 | X11: % EJECUCIÓN MP IM≥12 MENSUAL | Y11: =+'TABLA CÁLCULO'!B27 | Z11: =+'TABLA CÁLCULO'!C27 | AA11: =+'TABLA CÁLCULO'!D27 | AB11: =+'TABLA CÁLCULO'!E27 | AC11: =+'TABLA CÁLCULO'!F27 | AD11: =+'TABLA CÁLCULO'!G27 | AE11: =+'TABLA CÁLCULO'!H27 | AF11: =+'TABLA CÁLCULO'!I27 | ... AJ11: =+'TABLA CÁLCULO'!M27
A13: GASTO PROGRAMADO MC | B13: 400000000 | D13: EJECUCIÓN GASTO MC | E13: =+SUM('SEGUIMIENTO GASTO'!AG149:AG235) -> 15588666 | Q13: % EJECUCIÓN GASTO MP | T13: % EJECUCIÓN GASTO MC
Y14: CUMPLIMIENTO MANTENIMIENTO PREVENTIVO
A15: SERVICIO CLÍNICO | B15: RECINTO | C15: CLASE | D15: SUBCLASE | E15: NOMBRE EQUIPO | F15: MARCA | G15: MODELO | H15: SERIE | I15: N° INVENTARIO | J15: AÑO DE ADQUISICIÓN | K15: VIDA ÚTIL | L15: VIDA ÚTIL RESIDUAL | M15: PROPIO / ARRIENDO / COMODATO | N15: ESTADO (BUENO / REGULAR / MALO) | O15: CRÍTICO/ RELEVANTE / IM≥12 / NO APLICA | P15: EN GARANTÍA (SI / NO) | Q15: AÑO VENCIMIENTO GARANTÍA | R15: BAJO PLAN DE MANTENIMIENTO (SI / NO) | S15: AÑO INGRESO A PLAN DE MANTENIMIENTO (2023 / 2024 / 2025 / 2026) | T15: MANTENIMIENTO INTERNO O MANTENIMIENTO EXTERNO | U15: NOMBRE DE PROVEEDOR O MANTENIMIENTO INTERNO | V15: ID CONVENIO DE MANTENIMIENTO | W15: COSTO ANUAL DE MANTENIMIENTO SEGÚN CONVENIO / PRECIO DE REFERENCIA MANTENIMIENTO ANUAL | X15: FRECUENCIA ANUAL DE MANTENIMIENTO | Y15: ENERO | Z15: FEBRERO | AA15: MARZO | AB15: ABRIL | AC15: MAYO | AD15: JUNIO | AE15: JULIO | AF15: AGOSTO | AG15: SEPTIEMBRE | AH15: OCTUBRE | AI15: NOVIEMBRE | AJ15: DICIEMBRE
A16: Cirugía | B16: Hospital Regional Coyhaique | C16: monitoreo | D16: alto costo | E16: Monitor Desfibrilador | F16: Nihon Kohden | G16: TEC-5531E | H16: 02566 | I16: 0084-12 | J16: 2012 | K16: 10 | L16: =+IF(J16=0," ",K16-($B$9-J16)) -> -4 | M16: PROPIO | N16: MALO | O16: CRÍTICO | P16: NO | R16: SI | S16: 2026 | T16: Interna | U16: Interna | X16: 2 | AC16: X | AI16: X
A17: Medicina | B17: Hospital Regional Coyhaique | C17: monitoreo | D17: alto costo | E17: Monitor Desfibrilador | F17: Nihon Kohden | G17: TEC-5531E | H17: 02572 | I17: 0087-12 | J17: 2012 | K17: 10 | L17: =+IF(J17=0," ",K17-($B$9-J17)) -> -4 | M17: PROPIO | N17: MALO | O17: CRÍTICO | P17: NO | R17: SI | S17: 2026 | T17: Interna | U17: Interna | X17: 2 | AC17: X | AI17: X
A18: Maternidad | B18: Hospital Regional Coyhaique | C18: monitoreo | D18: alto costo | E18: Monitor Desfibrilador | F18: Nihon Kohden | G18: TEC-5531E | H18: 02583 | I18: 0086-12 | J18: 2012 | K18: 10 | L18: =+IF(J18=0," ",K18-($B$9-J18)) -> -4 | M18: PROPIO | N18: MALO | O18: CRÍTICO | P18: NO | R18: SI | S18: 2026 | T18: Interna | U18: Interna | X18: 2 | AC18: X | AI18: X
A19: Pediatria | B19: Hospital Regional Coyhaique | C19: monitoreo | D19: alto costo | E19: Monitor Desfibrilador | F19: Nihon Kohden | G19: TEC-5531E | H19: 02576 | I19: 0085-12 | J19: 2012 | K19: 10 | L19: =+IF(J19=0," ",K19-($B$9-J19)) -> -4 | M19: PROPIO | N19: MALO | O19: CRÍTICO | P19: NO | R19: SI | S19: 2026 | T19: Interna | U19: Interna | X19: 2 | AC19: X | AI19: X
A20: Pensionado | B20: Hospital Regional Coyhaique | C20: monitoreo | D20: alto costo | E20: Monitor Desfibrilador | F20: Nihon Kohden | G20: TEC-5531E | H20: 02567 | I20: 0088-12 | J20: 2012 | K20: 10 | L20: =+IF(J20=0," ",K20-($B$9-J20)) -> -4 | M20: PROPIO | N20: MALO | O20: CRÍTICO | P20: NO | R20: SI | S20: 2026 | T20: Interna | U20: Interna | X20: 2 | AC20: X | AI20: X
A21: Endoscopia | B21: Hospital Regional Coyhaique | C21: monitoreo | D21: alto costo | E21: Monitor Desfibrilador | F21: Nihon Kohden | G21: TEC-5531E | H21: 02485 | I21: 0031-12 | J21: 2012 | K21: 10 | L21: =+IF(J21=0," ",K21-($B$9-J21)) -> -4 | M21: PROPIO | N21: MALO | O21: CRÍTICO | P21: NO | R21: SI | S21: 2026 | T21: Interna | U21: Interna | X21: 2 | AC21: X | AI21: X
A22: Cardiologia | B22: Hospital Regional Coyhaique | C22: monitoreo | D22: alto costo | E22: Monitor Desfibrilador | F22: Nihon Kohden | G22: TEC-5531E | H22: 02486 | I22: 0030-12 | J22: 2012 | K22: 10 | L22: =+IF(J22=0," ",K22-($B$9-J22)) -> -4 | M22: PROPIO | N22: MALO | O22: CRÍTICO | P22: NO | R22: SI | S22: 2026 | T22: Interna | U22: Interna | X22: 2 | AC22: X | AI22: X
A23: Unidad Trat. Intermedio | B23: Hospital Regional Coyhaique | C23: monitoreo | D23: alto costo | E23: Monitor Desfibrilador | F23: Nihon Kohden | G23: TEC-5531E | H23: 02573 | I23: 0030-13 | J23: 2013 | K23: 10 | L23: =+IF(J23=0," ",K23-($B$9-J23)) -> -3 | M23: PROPIO | N23: MALO | O23: CRÍTICO | P23: NO | R23: SI | S23: 2026 | T23: Interna | U23: Interna | X23: 2 | AC23: X | AI23: X
A24: Uci adultos | B24: Hospital Regional Coyhaique | C24: monitoreo | D24: alto costo | E24: Monitor Desfibrilador | F24: Nihon Kohden | G24: TEC-5631E | H24: 00043 | I24: 0648-16 | J24: 2016 | K24: 10 | L24: =+IF(J24=0," ",K24-($B$9-J24)) -> 0 | M24: PROPIO | N24: MALO | O24: CRÍTICO | P24: NO | R24: SI | S24: 2026 | T24: Interna | U24: Interna | X24: 2 | AB24: X | AH24: X
A25: Uci adultos | B25: Hospital Regional Coyhaique | C25: monitoreo | D25: alto costo | E25: Monitor Desfibrilador | F25: Nihon Kohden | G25: TEC-5631E | H25: 00067 | I25: 0649-16 | J25: 2016 | K25: 10 | L25: =+IF(J25=0," ",K25-($B$9-J25)) -> 0 | M25: PROPIO | N25: MALO | O25: CRÍTICO | P25: NO | R25: SI | S25: 2026 | T25: Interna | U25: Interna | X25: 2 | AB25: X | AH25: X
A26: Policlínico de Especialidades / Vacunatorio | B26: Hospital Regional Coyhaique | C26: monitoreo | D26: alto costo | E26: Monitor Desfibrilador | F26: Zoll | G26: R Series | H26: AF12I024163 | I26: 0060-13 | J26: 2013 | K26: 10 | L26: =+IF(J26=0," ",K26-($B$9-J26)) -> -3 | M26: PROPIO | N26: MALO | O26: CRÍTICO | P26: NO | R26: SI | S26: 2026 | T26: Interna | U26: Interna | X26: 2 | Z26: X | AF26: X
A27: Dialisis | B27: Hospital Regional Coyhaique | C27: monitoreo | D27: alto costo | E27: Monitor Desfibrilador | F27: Zoll | G27: R Series | H27: AF17G068188 | I27: 1502-17 | J27: 2017 | K27: 10 | L27: =+IF(J27=0," ",K27-($B$9-J27)) -> 1 | M27: PROPIO | N27: MALO | O27: CRÍTICO | P27: NO | R27: SI | S27: 2026 | T27: Interna | U27: Interna | X27: 2 | Z27: X | AF27: X
A28: Pabellon quirurgico y anestesia | B28: Hospital Regional Coyhaique | C28: monitoreo | D28: alto costo | E28: Monitor Desfibrilador | F28: Zoll | G28: R Series | H28: AF13D028417 | I28: 0022-14 | J28: 2014 | K28: 10 | L28: =+IF(J28=0," ",K28-($B$9-J28)) -> -2 | M28: PROPIO | N28: MALO | O28: CRÍTICO | P28: NO | R28: SI | S28: 2026 | T28: Interna | U28: Interna | X28: 2 | Z28: X | AF28: X
A29: Pabellon quirurgico y anestesia | B29: Hospital Regional Coyhaique | C29: monitoreo | D29: alto costo | E29: Monitor Desfibrilador | F29: Zoll | G29: R Series | H29: AF13D028440 | I29: 0023-14 | J29: 2014 | K29: 10 | L29: =+IF(J29=0," ",K29-($B$9-J29)) -> -2 | M29: PROPIO | N29: MALO | O29: CRÍTICO | P29: NO | R29: SI | S29: 2026 | T29: Interna | U29: Interna | X29: 2 | Z29: X | AF29: X
A30: Ucin Neonatologia | B30: Hospital Regional Coyhaique | C30: monitoreo | D30: alto costo | E30: Monitor Desfibrilador | F30: Zoll | G30: R Series | H30: AF13H030686 | I30: 0024-14 | J30: 2014 | K30: 10 | L30: =+IF(J30=0," ",K30-($B$9-J30)) -> -2 | M30: PROPIO | N30: MALO | O30: CRÍTICO | P30: NO | R30: SI | S30: 2026 | T30: Interna | U30: Interna | X30: 2 | Z30: X | AF30: X
A31: Hospi. Domiciliaria | B31: Hospital Regional Coyhaique | C31: monitoreo | D31: alto costo | E31: Monitor Desfibrilador DEA | F31: Nihon Kohden | G31: AED 2100K | H31: 13046 | I31: 0423-15 | J31: 2015 | K31: 10 | L31: =+IF(J31=0," ",K31-($B$9-J31)) -> -1 | M31: PROPIO | N31: MALO | O31: CRÍTICO | P31: NO | R31: SI | S31: 2026 | T31: Interna | U31: Interna | X31: 2 | Y31: √ | AE31: X
A32: Pre-Parto | B32: Hospital Regional Coyhaique | C32: monitoreo | D32: alto costo | E32: Monitor Desfibrilador | F32: Nihon Kohden | G32: TEC-5631E | H32: 00029 | I32: 0647-16 | J32: 2016 | K32: 10 | L32: =+IF(J32=0," ",K32-($B$9-J32)) -> 0 | M32: PROPIO | N32: MALO | O32: CRÍTICO | P32: NO | R32: SI | S32: 2026 | T32: Interna | U32: Interna | X32: 2 | AB32: X | AH32: X
A33: Cardiologia | B33: Hospital Regional Coyhaique | C33: monitoreo | D33: alto costo | E33: Monitor Desfibrilador | F33: Nihon Kohden | G33: TEC-5631E | H33: 00038 | I33: 1162-17 | J33: 2017 | K33: 10 | L33: =+IF(J33=0," ",K33-($B$9-J33)) -> 1 | M33: PROPIO | N33: MALO | O33: CRÍTICO | P33: NO | R33: SI | S33: 2026 | T33: Interna | U33: Interna | X33: 2 | AB33: X | AH33: X
A34: Unidad Trat. Intermedio | B34: Hospital Regional Coyhaique | C34: monitoreo | D34: alto costo | E34: Monitor Desfibrilador | F34: Zoll | G34: M Series | H34: T08K107750 | I34: 1389 | K34: 10 | L34: =+IF(J34=0," ",K34-($B$9-J34)) | M34: PROPIO | N34: MALO | O34: CRÍTICO | P34: NO | R34: SI | S34: 2026 | T34: Interna | U34: Interna | X34: 2 | Z34: X | AF34: X
A35: Equipos Medicos | B35: Hospital Regional Coyhaique | C35: monitoreo | D35: alto costo | E35: Monitor Desfibrilador | F35: Nihon Kohden | G35: TEC-5521E | H35: 01543 | I35: 0030-11 | J35: 2011 | K35: 10 | L35: =+IF(J35=0," ",K35-($B$9-J35)) -> -5 | M35: PROPIO | N35: MALO | O35: CRÍTICO | P35: NO | R35: SI | S35: 2026 | T35: Interna | U35: Interna | X35: 2 | AB35: X | AH35: X
A36: UTI pediatrica | B36: Hospital Regional Coyhaique | C36: monitoreo | D36: alto costo | E36: Monitor Desfibrilador | F36: Zoll | G36: R Series | H36: AF15F047337 | I36: 0719-16 | J36: 2016 | K36: 10 | L36: =+IF(J36=0," ",K36-($B$9-J36)) -> 0 | M36: PROPIO | N36: MALO | O36: CRÍTICO | P36: NO | R36: SI | S36: 2026 | T36: Interna | U36: Interna | X36: 2 | Z36: X | AF36: X
A37: Pabellon quirurgico y anestesia | B37: Hospital Regional Coyhaique | C37: monitoreo | D37: alto costo | E37: Monitor Desfibrilador | F37: Zoll | G37: R Series | H37: AF18H083828 | I37: 17344 | J37: 2018 | K37: 10 | L37: =+IF(J37=0," ",K37-($B$9-J37)) -> 2 | M37: PROPIO | N37: MALO | O37: CRÍTICO | P37: NO | R37: SI | S37: 2026 | T37: Interna | U37: Interna | X37: 2 | AA37: X | AG37: X
A38: Pabellon quirurgico y anestesia | B38: Hospital Regional Coyhaique | C38: monitoreo | D38: alto costo | E38: Monitor Desfibrilador | F38: Zoll | G38: R Series | H38: AF18H083829 | I38: 17340 | J38: 2018 | K38: 10 | L38: =+IF(J38=0," ",K38-($B$9-J38)) -> 2 | M38: PROPIO | N38: MALO | O38: CRÍTICO | P38: NO | R38: SI | S38: 2026 | T38: Interna | U38: Interna | X38: 2 | AA38: X | AG38: X
A39: Pabellon quirurgico y anestesia | B39: Hospital Regional Coyhaique | C39: monitoreo | D39: alto costo | E39: Monitor Desfibrilador | F39: Zoll | G39: R Series | H39: AF19A090692 | I39: 17385 | J39: 2018 | K39: 10 | L39: =+IF(J39=0," ",K39-($B$9-J39)) -> 2 | M39: PROPIO | N39: MALO | O39: CRÍTICO | P39: NO | R39: SI | S39: 2026 | T39: Interna | U39: Interna | X39: 2 | Y39: √ | AE39: X
A40: Pabellon quirurgico y anestesia | B40: Hospital Regional Coyhaique | C40: monitoreo | D40: alto costo | E40: Monitor Desfibrilador | F40: Zoll | G40: R Series | H40: AF19A090702 | I40: 17386 | J40: 2018 | K40: 10 | L40: =+IF(J40=0," ",K40-($B$9-J40)) -> 2 | M40: PROPIO | N40: MALO | O40: CRÍTICO | P40: NO | R40: SI | S40: 2026 | T40: Interna | U40: Interna | X40: 2 | Y40: √ | AE40: X
A41: Medicina | B41: Hospital Regional Coyhaique | C41: monitoreo | D41: alto costo | E41: Monitor Desfibrilador | F41: Philips | G41: Efficia DFM100 | H41: CN32629235 | I41: 17961 | J41: 2018 | K41: 10 | L41: =+IF(J41=0," ",K41-($B$9-J41)) -> 2 | M41: PROPIO | N41: MALO | O41: CRÍTICO | P41: NO | R41: SI | S41: 2026 | T41: Interna | U41: Interna | X41: 2 | AC41: X | AI41: X
A42: Urgencia | B42: Hospital Regional Coyhaique | C42: monitoreo | D42: alto costo | E42: Monitor Desfibrilador | F42: Zoll | G42: M2 | H42: BA19C000002 | I42: 18039 | J42: 2020 | K42: 10 | L42: =+IF(J42=0," ",K42-($B$9-J42)) -> 4 | M42: PROPIO | N42: REGULAR | O42: CRÍTICO | P42: NO | R42: SI | S42: 2026 | T42: Interna | U42: Interna | X42: 2 | AD42: X | AJ42: X
A43: Urgencia | B43: Hospital Regional Coyhaique | C43: monitoreo | D43: alto costo | E43: Monitor Desfibrilador | F43: Zoll | G43: M2 | H43: BA20F000016 | I43: 18102 | J43: 2020 | K43: 10 | L43: =+IF(J43=0," ",K43-($B$9-J43)) -> 4 | M43: PROPIO | N43: REGULAR | O43: CRÍTICO | P43: NO | Q43: 03.08.21 | R43: SI | S43: 2026 | T43: Interna | U43: Interna | X43: 2 | Z43: X | AF43: X
A44: Urgencia | B44: Hospital Regional Coyhaique | C44: monitoreo | D44: alto costo | E44: Monitor Desfibrilador | F44: Zoll | G44: M2 | H44: BA20F000014 | I44: 18101 | J44: 2020 | K44: 10 | L44: =+IF(J44=0," ",K44-($B$9-J44)) -> 4 | M44: PROPIO | N44: REGULAR | O44: CRÍTICO | P44: NO | Q44: 03.08.21 | R44: SI | S44: 2026 | T44: Interna | U44: Interna | X44: 2 | Z44: X | AF44: X
A45: Imageonología (Resonador Magnetico) | B45: Hospital Regional Coyhaique | C45: monitoreo | D45: alto costo | E45: Monitor Desfibrilador | F45: CU Medical | G45: HD-1 | H45: M2S23G079 | I45: 18839 | J45: 2022 | K45: 10 | L45: =+IF(J45=0," ",K45-($B$9-J45)) -> 6 | M45: PROPIO | N45: BUENO | O45: CRÍTICO | P45: SI | Q45: 09.01.26 | R45: SI | S45: 2026 | T45: EXTERNO | U45: Medcasem (G) | X45: 2 | Y45: √ | AE45: X
...

Sheet SEGUIMIENTO GASTO
B3: SEGUIMIENTO GASTO CONVENIOS DE MANTENIMIENTO
K5: CONTROL MENSUAL EJECUCIÓN
K6: ENERO | M6: FEBRERO | O6: MARZO | Q6: ABRIL | S6: MAYO | U6: JUNIO | W6: JULIO | Y6: AGOSTO | AA6: SEPTIEMBRE | AC6: OCTUBRE | AE6: NOVIEMBRE | AG6: DICIEMBRE
B7: Nº | C7: SERVICIO DE SALUD | D7: ESTABLECIMIENTO | E7: NOMBRE CONVENIO DE MANTENIMIENTO | F7: Nº RESOLUCIÓN / ID / ORDEN DE COMPRA DEL CONVENIO | G7: FECHA RESOLUCIÓN | H7: FECHA DE EXPIRACION CONVENIO | I7: MONTO ANUAL ($) | J7: SUBASIGNACIÓN SIGFE | K7: N° ORDEN DE COMPRA / N° FACTURA | L7: MONTO ($) | M7: N° ORDEN DE COMPRA / N° FACTURA | N7: MONTO ($) | O7: N° ORDEN DE COMPRA / N° FACTURA | P7: MONTO ($) | Q7: N° ORDEN DE COMPRA / N° FACTURA | R7: MONTO ($) | S7: N° ORDEN DE COMPRA / N° FACTURA | T7: MONTO ($) | U7: N° ORDEN DE COMPRA / N° FACTURA | V7: MONTO ($) | W7: N° ORDEN DE COMPRA / N° FACTURA | X7: MONTO ($) | Y7: N° ORDEN DE COMPRA / N° FACTURA | Z7: MONTO ($) | AA7: N° ORDEN DE COMPRA / N° FACTURA | AB7: MONTO ($) | AC7: N° ORDEN DE COMPRA / N° FACTURA | AD7: MONTO ($) | AE7: N° ORDEN DE COMPRA / N° FACTURA | AF7: MONTO ($) | AG7: N° ORDEN DE COMPRA / N° FACTURA | AH7: MONTO ($) | AI7: TOTAL
B8: 1 | C8: AYSEN | D8: Hospital Regional Coyhaique | E8: ORDENES 2025 SIN PAGO, ESPERANDO REGULARIZACION PRESUPUESTO 2026 | J8: 22.06.006.003 | L8: 0 | N8: 0 | P8: 0 | R8: 0 | T8: 0 | V8: 0 | X8: 0 | Z8: 0 | AB8: 0 | AD8: 0 | AF8: 0 | AH8: 0 | AI8: =+L8+N8+P8+R8+T8+V8+X8+Z8+AB8+AD8+AF8+AH8 -> 0
B9: 2 | C9: AYSEN | D9: Hospital Regional Coyhaique | E9: CONVENIO ANDOVER RES 10016 Y 14499 | F9: 1366597-2998-TD25 | G9: 45142 | H9: 46238 | I9: 4329719 | J9: 22.06.006.003 | L9: 0 | N9: 0 | P9: 0 | R9: 0 | T9: 0 | V9: 0 | X9: 0 | Z9: 0 | AB9: 0 | AD9: 0 | AF9: 0 | AH9: 0 | AI9: =+L9+N9+P9+R9+T9+V9+X9+Z9+AB9+AD9+AF9+AH9 -> 0
B10: 3 | C10: AYSEN | D10: Hospital Regional Coyhaique | F10: 1366597-3463-TD25 | I10: 4329719 | J10: 22.06.006.003 | L10: 0 | M10: 1366597-3463-TD25 | N10: 4329719 | P10: 0 | R10: 0 | T10: 0 | V10: 0 | X10: 0 | Z10: 0 | AB10: 0 | AD10: 0 | AF10: 0 | AH10: 0 | AI10: =+L10+N10+P10+R10+T10+V10+X10+Z10+AB10+AD10+AF10+AH10 -> 4329719
B11: 4 | C11: AYSEN | D11: Hospital Regional Coyhaique | F11: 1366597-3692-TD25 | I11: 4329719 | J11: 22.06.006.003 | M11: 1366597-3692-TD25 | N11: 4329719 | P11: 0 | R11: 0 | T11: 0 | V11: 0 | X11: 0 | Z11: 0 | AB11: 0 | AD11: 0 | AF11: 0 | AH11: 0 | AI11: =+L11+N11+P11+R11+T11+V11+X11+Z11+AB11+AD11+AF11+AH11 -> 4329719
B12: 5 | C12: AYSEN | D12: Hospital Regional Coyhaique | F12: 1366597-3999-TD25 | I12: 4329719 | J12: 22.06.006.003 | L12: 0 | M12: 1366597-3999-TD25 | N12: 4329719 | P12: 0 | R12: 0 | T12: 0 | V12: 0 | X12: 0 | Z12: 0 | AB12: 0 | AD12: 0 | AF12: 0 | AH12: 0 | AI12: =+L12+N12+P12+R12+T12+V12+X12+Z12+AB12+AD12+AF12+AH12 -> 4329719
B13: 6 | C13: AYSEN | D13: Hospital Regional Coyhaique | E13: CONVENIO PHILIPS EQUIPO DE RAYOS RES 10851 PAGADO CON PRESUPUESTO 2026 | F13: 1366597-4052-TD25 | G13: 45843 | H13: 46208 | I13: 14077700 | J13: 22.06.006.003 | K13: 1366597-4052-TD25 | L13: 14077700 | N13: 0 | P13: 0 | R13: 0 | T13: 0 | V13: 0 | X13: 0 | Z13: 0 | AB13: 0 | AD13: 0 | AF13: 0 | AH13: 0 | AI13: =+L13+N13+P13+R13+T13+V13+X13+Z13+AB13+AD13+AF13+AH13 -> 14077700
B14: 7 | C14: AYSEN | D14: Hospital Regional Coyhaique | F14: 1366597-4054-TD25 | I14: 14077700 | J14: 22.06.006.003 | K14: 1366597-4054-TD25 | L14: 14077700 | N14: 0 | P14: 0 | R14: 0 | T14: 0 | V14: 0 | X14: 0 | Z14: 0 | AB14: 0 | AD14: 0 | AF14: 0 | AH14: 0 | AI14: =+L14+N14+P14+R14+T14+V14+X14+Z14+AB14+AD14+AF14+AH14 -> 14077700
B15: 8 | C15: AYSEN | D15: Hospital Regional Coyhaique | F15: 1366597-4055-TD25 | I15: 14077700 | J15: 22.06.006.003 | K15: 1366597-4055-TD25 | L15: 14077700 | N15: 0 | P15: 0 | R15: 0 | T15: 0 | V15: 0 | X15: 0 | Z15: 0 | AB15: 0 | AD15: 0 | AF15: 0 | AH15: 0 | AI15: =+L15+N15+P15+R15+T15+V15+X15+Z15+AB15+AD15+AF15+AH15 -> 14077700
B16: 9 | C16: AYSEN | D16: Hospital Regional Coyhaique | F16: 1366597-4056-TD25 | I16: 14077700 | J16: 22.06.006.003 | K16: 1366597-4056-TD25 | L16: 14077700 | N16: 0 | P16: 0 | R16: 0 | T16: 0 | V16: 0 | X16: 0 | Z16: 0 | AB16: 0 | AD16: 0 | AF16: 0 | AH16: 0 | AI16: =+L16+N16+P16+R16+T16+V16+X16+Z16+AB16+AD16+AF16+AH16 -> 14077700
B17: 10 | C17: AYSEN | D17: Hospital Regional Coyhaique | E17: CONVENIO AGFA 6346 | F17: 1366597-2225-TD25 | G17: 45413 | H17: 46142 | I17: 877587 | J17: 22.06.006.003 | L17: 0 | N17: 0 | P17: 0 | R17: 0 | T17: 0 | V17: 0 | X17: 0 | Z17: 0 | AB17: 0 | AD17: 0 | AF17: 0 | AH17: 0 | AI17: =+L17+N17+P17+R17+T17+V17+X17+Z17+AB17+AD17+AF17+AH17 -> 0
B18: 11 | C18: AYSEN | D18: Hospital Regional Coyhaique | F18: 1366597-2995-TD25 | I18: 877587 | J18: 22.06.006.003 | L18: 0 | N18: 0 | P18: 0 | R18: 0 | T18: 0 | V18: 0 | X18: 0 | Z18: 0 | AB18: 0 | AD18: 0 | AF18: 0 | AH18: 0 | AI18: =+L18+N18+P18+R18+T18+V18+X18+Z18+AB18+AD18+AF18+AH18 -> 0
B19: 12 | C19: AYSEN | D19: Hospital Regional Coyhaique | F19: 1366597-3338-TD25 | I19: 877587 | J19: 22.06.006.003 | K19: 1366597-3338-TD25 | L19: 877587 | N19: 0 | P19: 0 | R19: 0 | T19: 0 | V19: 0 | X19: 0 | Z19: 0 | AB19: 0 | AD19: 0 | AF19: 0 | AH19: 0 | AI19: =+L19+N19+P19+R19+T19+V19+X19+Z19+AB19+AD19+AF19+AH19 -> 877587
B20: 13 | C20: AYSEN | D20: Hospital Regional Coyhaique | F20: 1366597-3691-TD25 | I20: 877587 | J20: 22.06.006.003 | K20: 1366597-3691-TD25 | L20: 877587 | N20: 0 | P20: 0 | R20: 0 | T20: 0 | V20: 0 | X20: 0 | Z20: 0 | AB20: 0 | AD20: 0 | AF20: 0 | AH20: 0 | AI20: =+L20+N20+P20+R20+T20+V20+X20+Z20+AB20+AD20+AF20+AH20 -> 877587
B21: 14 | C21: AYSEN | D21: Hospital Regional Coyhaique | F21: 1366597-3994-TD25 | I21: 877587 | J21: 22.06.006.003 | L21: 0 | N21: 0 | P21: 0 | R21: 0 | T21: 0 | V21: 0 | X21: 0 | Z21: 0 | AB21: 0 | AD21: 0 | AF21: 0 | AH21: 0 | AI21: =+L21+N21+P21+R21+T21+V21+X21+Z21+AB21+AD21+AF21+AH21 -> 0
B22: 15 | C22: AYSEN | D22: Hospital Regional Coyhaique | E22: CONVENIO RESONADOR 16341 PAGADO CON PRESUPUESTO 2026 | F22: 1366597-3666-TD25 | G22: 45931 | H22: 46296 | I22: 10259287 | J22: 22.06.006.003 | K22: 1366597-3666-TD25 | L22: 10259287 | N22: 0 | P22: 0 | R22: 0 | T22: 0 | V22: 0 | X22: 0 | Z22: 0 | AB22: 0 | AD22: 0 | AF22: 0 | AH22: 0 | AI22: =+L22+N22+P22+R22+T22+V22+X22+Z22+AB22+AD22+AF22+AH22 -> 10259287
B23: 16 | C23: AYSEN | D23: Hospital Regional Coyhaique | F23: 1366597-4003-TD25 | I23: 10259287 | J23: 22.06.006.003 | K23: 1366597-4003-TD25 | L23: 10259287 | N23: 0 | P23: 0 | R23: 0 | T23: 0 | V23: 0 | X23: 0 | Z23: 0 | AB23: 0 | AD23: 0 | AF23: 0 | AH23: 0 | AI23: =+L23+N23+P23+R23+T23+V23+X23+Z23+AB23+AD23+AF23+AH23 -> 10259287
B24: 17 | H24: deuda en convenios 2025 | I24: =I9+I10+I11+I12+I17+I18+I19+I20+I21 -> 21706811
B25: 18 | C25: AYSEN | D25: Hospital Regional Coyhaique | E25: ORDENES 2025 SIN PAGO, ESPERANDO REGULARIZACION PRESUPUESTO 2026 | I25: 0 | J25: 22.06.006.003 | L25: 0 | N25: 0 | P25: 0 | R25: 0 | T25: 0 | V25: 0 | X25: 0 | Z25: 0 | AB25: 0 | AD25: 0 | AF25: 0 | AH25: 0 | AI25: =+L25+N25+P25+R25+T25+V25+X25+Z25+AB25+AD25+AF25+AH25 -> 0
B26: 19 | C26: AYSEN | D26: Hospital Regional Coyhaique | E26: MANTENCION PREVENTIVA BBRAUN FINALIZADA CON ERROR EN EL DEVENGO | F26: 4778-312-TD25 | I26: 1748983 | J26: 22.06.006.003 | L26: 0 | N26: 0 | P26: 0 | R26: 0 | T26: 0 | V26: 0 | X26: 0 | Z26: 0 | AB26: 0 | AD26: 0 | AF26: 0 | AH26: 0 | AI26: =+L26+N26+P26+R26+T26+V26+X26+Z26+AB26+AD26+AF26+AH26 -> 0
B27: 20 | C27: AYSEN | D27: Hospital Regional Coyhaique | E27: MANTENCION PREVENTIVA ROCHEM FINALIZADA CON ERROR EN EL DEVENGO | F27: 4778-350-TD25 | I27: 2023000 | J27: 22.06.006.003 | L27: 0 | N27: 0 | P27: 0 | R27: 0 | T27: 0 | V27: 0 | X27: 0 | Z27: 0 | AB27: 0 | AD27: 0 | AF27: 0 | AH27: 0 | AI27: =+L27+N27+P27+R27+T27+V27+X27+Z27+AB27+AD27+AF27+AH27 -> 0
B28: 21 | C28: AYSEN | D28: Hospital Regional Coyhaique | E28: MANTENCION PREVENTIVA MEDPLAN FINALIZADA CON ERROR EN EL DEVENGO | F28: 4778-409-TD25 | I28: 1068620 | J28: 22.06.006.003 | L28: 0 | N28: 0 | P28: 0 | R28: 0 | T28: 0 | V28: 0 | X28: 0 | Z28: 0 | AB28: 0 | AD28: 0 | AF28: 0 | AH28: 0 | AI28: =+L28+N28+P28+R28+T28+V28+X28+Z28+AB28+AD28+AF28+AH28 -> 0
B29: 22 | C29: AYSEN | D29: Hospital Regional Coyhaique | E29: MANTENCION PREVENTIVA BIOMERIUX FINALIZADA CON ERROR EN EL DEVENGO | F29: 4778-441-TD25 | I29: 4485762 | J29: 22.06.006.003 | L29: 0 | N29: 0 | P29: 0 | R29: 0 | T29: 0 | V29: 0 | X29: 0 | Z29: 0 | AB29: 0 | AD29: 0 | AF29: 0 | AH29: 0 | AI29: =+L29+N29+P29+R29+T29+V29+X29+Z29+AB29+AD29+AF29+AH29 -> 0
B30: 23 | C30: AYSEN | D30: Hospital Regional Coyhaique | E30: MANTENCION PREVENTIVA DRAGER FINALIZADA CON ERROR EN EL DEVENGO | F30: 4778-439-TD25 | I30: 2210187 | J30: 22.06.006.003 | L30: 0 | N30: 0 | P30: 0 | R30: 0 | T30: 0 | V30: 0 | X30: 0 | Z30: 0 | AB30: 0 | AD30: 0 | AF30: 0 | AH30: 0 | AI30: =+L30+N30+P30+R30+T30+V30+X30+Z30+AB30+AD30+AF30+AH30 -> 0
B31: 25 | C31: AYSEN | D31: Hospital Regional Coyhaique | E31: MANTENCION PREVENTIVA TECNOIMAGEN FINALIZADA CON ERROR EN EL DEVENGO | F31: 4778-444-TD25 | I31: 5913907 | J31: 22.06.006.003 | L31: 0 | N31: 0 | P31: 0 | R31: 0 | T31: 0 | V31: 0 | X31: 0 | Z31: 0 | AB31: 0 | AD31: 0 | AF31: 0 | AH31: 0 | AI31: =+L31+N31+P31+R31+T31+V31+X31+Z31+AB31+AD31+AF31+AH31 -> 0
B32: 26 | C32: AYSEN | D32: Hospital Regional Coyhaique | E32: MANTENCION PREVENTIVA HEMIFERIO FINALIZADA CON ERROR EN EL DEVENGO | F32: 4778-469-TD25 | I32: 13435100 | J32: 22.06.006.003 | L32: 0 | N32: 0 | P32: 0 | R32: 0 | T32: 0 | V32: 0 | X32: 0 | Z32: 0 | AB32: 0 | AD32: 0 | AF32: 0 | AH32: 0 | AI32: =+L32+N32+P32+R32+T32+V32+X32+Z32+AB32+AD32+AF32+AH32 -> 0
B33: 27 | C33: AYSEN | D33: Hospital Regional Coyhaique | E33: MANTENCION PREVENTIVA FULLTECHNOLOGY FINALIZADA CON ERROR EN EL DEVENGO | F33: 4778-504-TD25 | I33: 4438700 | J33: 22.06.006.003 | L33: 0 | N33: 0 | P33: 0 | R33: 0 | T33: 0 | V33: 0 | X33: 0 | Z33: 0 | AB33: 0 | AD33: 0 | AF33: 0 | AH33: 0 | AI33: =+L33+N33+P33+R33+T33+V33+X33+Z33+AB33+AD33+AF33+AH33 -> 0
B34: 28 | C34: AYSEN | D34: Hospital Regional Coyhaique | E34: MANTENCION PREVENTIVA CENTRAL DE COMPRAS DEL EXTRASISTEMA S.A. FINALIZADA CON ERROR EN EL DEVENGO | F34: 4778-506-TD25 | I34: 4231640 | J34: 22.06.006.003 | L34: 0 | N34: 0 | P34: 0 | R34: 0 | T34: 0 | V34: 0 | X34: 0 | Z34: 0 | AB34: 0 | AD34: 0 | AF34: 0 | AH34: 0 | AI34: =+L34+N34+P34+R34+T34+V34+X34+Z34+AB34+AD34+AF34+AH34 -> 0
B35: 29 | C35: AYSEN | D35: Hospital Regional Coyhaique | E35: MANTENCION PREVENTIVA PV EQUIP FINALIZADA CON ERROR EN EL DEVENGO | F35: 4778-509-TD25 | I35: 24112369 | J35: 22.06.006.003 | L35: 0 | N35: 0 | P35: 0 | R35: 0 | T35: 0 | V35: 0 | X35: 0 | Z35: 0 | AB35: 0 | AD35: 0 | AF35: 0 | AH35: 0 | AI35: =+L35+N35+P35+R35+T35+V35+X35+Z35+AB35+AD35+AF35+AH35 -> 0
B36: 30 | C36: AYSEN | D36: Hospital Regional Coyhaique | E36: MANTENCION PREVENTIVA ASP FINALIZADA CON ERROR EN EL DEVENGO | F36: 4778-501-TD25 | I36: 5611255 | J36: 22.06.006.003 | L36: 0 | N36: 0 | P36: 0 | R36: 0 | T36: 0 | V36: 0 | X36: 0 | Z36: 0 | AB36: 0 | AD36: 0 | AF36: 0 | AH36: 0 | AI36: =+L36+N36+P36+R36+T36+V36+X36+Z36+AB36+AD36+AF36+AH36 -> 0
B37: 32 | C37: AYSEN | D37: Hospital Regional Coyhaique | E37: MANTENCION PREVENTIVA GRUPO BIOS FINALIZADA CON ERROR EN EL DEVENGO | F37: 4778-577-TD25 | I37: 1480658 | J37: 22.06.006.003 | L37: 0 | N37: 0 | P37: 0 | R37: 0 | T37: 0 | V37: 0 | X37: 0 | Z37: 0 | AB37: 0 | AD37: 0 | AF37: 0 | AH37: 0 | AI37: =+L37+N37+P37+R37+T37+V37+X37+Z37+AB37+AD37+AF37+AH37 -> 0
... B44: 39 | C44: AYSEN | D44: Hospital Regional Coyhaique | E44: MANTENCION PREVENTIVA GRUPO BIOS TODAVIA NO SE REALIZA LA MANTENCION SIN RC | F44: 4778-551-TD25 | I44: 1269135 | J44: 22.06.006.003 | L44: 0 | N44: 0 | P44: 0 | R44: 0 | T44: 0 | V44: 0 | X44: 0 | Z44: 0 | AB44: 0 | AD44: 0 | AF44: 0 | AH44: 0 | AI44: =+L44+N44+P44+R44+T44+V44+X44+Z44+AB44+AD44+AF44+AH44 -> 0
B45: 40 | C45: AYSEN | D45: Hospital Regional Coyhaique | E45: MANTENCION PREVENTIVA INGENIERIA E IMPORTACIONES M & M LTDA. DEVENGO MANUAL CON PRESUPUESTO 2026 | F45: 4778-532-TD25 | H45: 46034 | I45: 1416100 | J45: 22.06.006.003 | K45: 4778-532-TD25 | L45: 1416100 | N45: 0 | P45: 0 | R45: 0 | T45: 0 | V45: 0 | X45: 0 | Z45: 0 | AB45: 0 | AD45: 0 | AF45: 0 | AH45: 0 | AI45: =+L45+N45+P45+R45+T45+V45+X45+Z45+AB45+AD45+AF45+AH45 -> 1416100
B46: 41 | C46: AYSEN | D46: Hospital Regional Coyhaique | E46: MANTENCION PREVENTIVA PVEQUIP FINALIZADA CON ERROR EN EL DEVENGO | F46: 4778-557-TD25 | I46: 5057348 | J46: 22.06.006.003 | L46: 0 | N46: 0 | P46: 0 | R46: 0 | T46: 0 | V46: 0 | X46: 0 | Z46: 0 | AB46: 0 | AD46: 0 | AF46: 0 | AH46: 0 | AI46: =+L46+N46+P46+R46+T46+V46+X46+Z46+AB46+AD46+AF46+AH46 -> 0
B47: 42 | C47: AYSEN | D47: Hospital Regional Coyhaique | E47: MANTENCION PREVENTIVA MEDTRONIC FINALIZADA PROBLEMA RECEPCION CONFORME | F47: 4778-555-TD25 | I47: 7145236 | J47: 22.06.006.003 | L47: 0 | N47: 0 | P47: 0 | R47: 0 | T47: 0 | V47: 0 | X47: 0 | Z47: 0 | AB47: 0 | AD47: 0 | AF47: 0 | AH47: 0 | AI47: =+L47+N47+P47+R47+T47+V47+X47+Z47+AB47+AD47+AF47+AH47 -> 0
B48: 43 | C48: AYSEN | D48: Hospital Regional Coyhaique | E48: MANTENCION PREVENTIVA HEMIFERIO FINALIZADA CON ERROR EN EL DEVENGO | F48: 4778-582-TD25 | I48: 4046000 | J48: 22.06.006.003 | L48: 0 | N48: 0 | P48: 0 | R48: 0 | T48: 0 | V48: 0 | X48: 0 | Z48: 0 | AB48: 0 | AD48: 0 | AF48: 0 | AH48: 0 | AI48: =+L48+N48+P48+R48+T48+V48+X48+Z48+AB48+AD48+AF48+AH48 -> 0
B49: 44 | C49: AYSEN | D49: Hospital Regional Coyhaique | E49: MANTENCION PREVENTIVA ANDOVER FINALIZADA EL PROVEEDOR LE FALTA FACTURAR | F49: 4778-710-TD25 | I49: 1904873 | J49: 22.06.006.003 | K49: 4778-710-TD25 | L49: 1904873 | N49: 0 | P49: 0 | R49: 0 | T49: 0 | V49: 0 | X49: 0 | Z49: 0 | AB49: 0 | AD49: 0 | AF49: 0 | AH49: 0 | AI49: =+L49+N49+P49+R49+T49+V49+X49+Z49+AB49+AD49+AF49+AH49 -> 1904873
...

Sheet TABLA CÁLCULO
A3: Etiquetas de fila | B3: Suma de FRECUENCIA ANUAL DE MANTENIMIENTO
A4: CRÍTICO | B4: 6
A5: IM ≥ 12 | B5: 6
A6: RELEVANTE | B6: 3
A7: (en blanco)
A8: Total general | B8: 15
A12: N° MP PROGRAMADAS | O12: TOTAL MP PROGRAMADAS | P12: =+GETPIVOTDATA("FRECUENCIA ANUAL DE MANTENIMIENTO",$A$49,"AÑO INGRESO A PLAN DE MANTENIMIENTO (2023 / 2024 / 2025 / 2026)",2023) -> 10
A13: N° MP EJECUTADAS | B13: =+COUNTIF('CATASTRO Y PLANIFICACIÓN MP'!Y16:Y4956,"√") -> 76 | C13: =+COUNTIF('CATASTRO Y PLANIFICACIÓN MP'!Z16:Z4956,"√") -> 0 | D13: =+COUNTIF('CATASTRO Y PLANIFICACIÓN MP'!AA16:AA4956,"√") -> 0 | E13: =+COUNTIF('CATASTRO Y PLANIFICACIÓN MP'!AB16:AB4956,"√") -> 0 | F13: =+COUNTIF('CATASTRO Y PLANIFICACIÓN MP'!AC16:AC4956,"√") -> 0 | G13: =+COUNTIF('CATASTRO Y PLANIFICACIÓN MP'!AD16:AD4956,"√") -> 0 | H13: =+COUNTIF('CATASTRO Y PLANIFICACIÓN MP'!AE16:AE4956,"√") -> 0 | I13: =+COUNTIF('CATASTRO Y PLANIFICACIÓN MP'!AF16:AF4956,"√") -> 0 | ... M13: =+COUNTIF('CATASTRO Y PLANIFICACIÓN MP'!AJ16:AJ4956,"√") -> 0 | O13: TOTAL MP EJECUTADAS | P13: =+SUM(B13:M13) -> 76 | R13: X | S13: PROGRAMADO | U13: CRÍTICO | W13: SI | Y13: 2023 | AA13: INTERNO | AC13: 1 | AE13: PROPIO | AF13: BUENO
A14: N° MP REPROGRAMADAS | B14: =+COUNTIF('CATASTRO Y PLANIFICACIÓN MP'!Y16:Y4957,"ꓣ") -> 0 | C14: =+COUNTIF('CATASTRO Y PLANIFICACIÓN MP'!Z16:Z4957,"ꓣ") -> 0 | D14: =+COUNTIF('CATASTRO Y PLANIFICACIÓN MP'!AA16:AA4957,"ꓣ") -> 0 | E14: =+COUNTIF('CATASTRO Y PLANIFICACIÓN MP'!AB16:AB4957,"ꓣ") -> 0 | F14: =+COUNTIF('CATASTRO Y PLANIFICACIÓN MP'!AC16:AC4957,"ꓣ") -> 0 | G14: =+COUNTIF('CATASTRO Y PLANIFICACIÓN MP'!AD16:AD4957,"ꓣ") -> 0 | H14: =+COUNTIF('CATASTRO Y PLANIFICACIÓN MP'!AE16:AE4957,"ꓣ") -> 0 | I14: =+COUNTIF('CATASTRO Y PLANIFICACIÓN MP'!AF16:AF4957,"ꓣ") -> 0 | ... M14: =+COUNTIF('CATASTRO Y PLANIFICACIÓN MP'!AJ16:AJ4957,"ꓣ") -> 0 | O14: TOTAL MP REPROGRAMADAS | P14: =+SUM(B14:M14) -> 0 | R14: √ | S14: REALIZADO | U14: RELEVANTE | W14: NO | Y14: 2024 | AA14: EXTERNO | AC14: 2 | AE14: ARRIENDO | AF14: REGULAR
O15: TOTAL MP PROGRAMADAS EQC | P15: =+GETPIVOTDATA("FRECUENCIA ANUAL DE MANTENIMIENTO",$A$49,"CRÍTICO/ RELEVANTE / IM≥12 / NO APLICA","CRÍTICO","AÑO INGRESO A PLAN DE MANTENIMIENTO (2023 / 2024 / 2025 / 2026)",2023) -> 6 | R15: ꓣ | S15: REPROGRAMADO | U15: IM ≥ 12 | Y15: 2025 | AC15: 3 | AE15: COMODATO | AF15: MALO
A16: N° MP EJECUTADAS EQC | B16: =+COUNTIFS('CATASTRO Y PLANIFICACIÓN MP'!$O$16:$O$4951,"CRÍTICO",'CATASTRO Y PLANIFICACIÓN MP'!Y16:Y4951,"√") -> 65 | C16: =+COUNTIFS('CATASTRO Y PLANIFICACIÓN MP'!$O$16:$O$4951,"CRÍTICO",'CATASTRO Y PLANIFICACIÓN MP'!Z16:Z4951,"√") -> 0 | D16: =+COUNTIFS('CATASTRO Y PLANIFICACIÓN MP'!$O$16:$O$4951,"CRÍTICO",'CATASTRO Y PLANIFICACIÓN MP'!AA16:AA4951,"√") -> 0 | E16: =+COUNTIFS('CATASTRO Y PLANIFICACIÓN MP'!$O$16:$O$4951,"CRÍTICO",'CATASTRO Y PLANIFICACIÓN MP'!AB16:AB4951,"√") -> 0 | F16: =+COUNTIFS('CATASTRO Y PLANIFICACIÓN MP'!$O$16:$O$4951,"CRÍTICO",'CATASTRO Y PLANIFICACIÓN MP'!AC16:AC4951,"√") -> 0 | G16: =+COUNTIFS('CATASTRO Y PLANIFICACIÓN MP'!$O$16:$O$4951,"CRÍTICO",'CATASTRO Y PLANIFICACIÓN MP'!AD16:AD4951,"√") -> 0 | H16: =+COUNTIFS('CATASTRO Y PLANIFICACIÓN MP'!$O$16:$O$4951,"CRÍTICO",'CATASTRO Y PLANIFICACIÓN MP'!AE16:AE4951,"√") -> 0 | I16: =+COUNTIFS('CATASTRO Y PLANIFICACIÓN MP'!$O$16:$O$4951,"CRÍTICO",'CATASTRO Y PLANIFICACIÓN MP'!AF16:AF4951,"√") -> 0 | ... M16: =+COUNTIFS('CATASTRO Y PLANIFICACIÓN MP'!$O$16:$O$4951,"CRÍTICO",'CATASTRO Y PLANIFICACIÓN MP'!AJ16:AJ4951,"√") -> 0 | O16: TOTAL MP PROGRAMADAS EQR | P16: =+GETPIVOTDATA("FRECUENCIA ANUAL DE MANTENIMIENTO",$A$49,"CRÍTICO/ RELEVANTE / IM≥12 / NO APLICA","RELEVANTE","AÑO INGRESO A PLAN DE MANTENIMIENTO (2023 / 2024 / 2025 / 2026)",2023) -> 1 | U16: NO APLICA | Y16: 2026 | AC16: 4 | AE16: PRÉSTAMO
A17: N° MP EJECUTADAS EQR | B17: =+COUNTIFS('CATASTRO Y PLANIFICACIÓN MP'!$O$16:$O$4951,"RELEVANTE",'CATASTRO Y PLANIFICACIÓN MP'!Y16:Y4951,"√") -> 11 | C17: =+COUNTIFS('CATASTRO Y PLANIFICACIÓN MP'!$O$16:$O$4951,"RELEVANTE",'CATASTRO Y PLANIFICACIÓN MP'!Z16:Z4951,"√") -> 0 | D17: =+COUNTIFS('CATASTRO Y PLANIFICACIÓN MP'!$O$16:$O$4951,"RELEVANTE",'CATASTRO Y PLANIFICACIÓN MP'!AA16:AA4951,"√") -> 0 | E17: =+COUNTIFS('CATASTRO Y PLANIFICACIÓN MP'!$O$16:$O$4951,"RELEVANTE",'CATASTRO Y PLANIFICACIÓN MP'!AB16:AB4951,"√") -> 0 | F17: =+COUNTIFS('CATASTRO Y PLANIFICACIÓN MP'!$O$16:$O$4951,"RELEVANTE",'CATASTRO Y PLANIFICACIÓN MP'!AC16:AC4951,"√") -> 0 | G17: =+COUNTIFS('CATASTRO Y PLANIFICACIÓN MP'!$O$16:$O$4951,"RELEVANTE",'CATASTRO Y PLANIFICACIÓN MP'!AD16:AD4951,"√") -> 0 | H17: =+COUNTIFS('CATASTRO Y PLANIFICACIÓN MP'!$O$16:$O$4951,"RELEVANTE",'CATASTRO Y PLANIFICACIÓN MP'!AE16:AE4951,"√") -> 0 | I17: =+COUNTIFS('CATASTRO Y PLANIFICACIÓN MP'!$O$16:$O$4951,"RELEVANTE",'CATASTRO Y PLANIFICACIÓN MP'!AF16:AF4951,"√") -> 0 | ... M17: =+COUNTIFS('CATASTRO Y PLANIFICACIÓN MP'!$O$16:$O$4951,"RELEVANTE",'CATASTRO Y PLANIFICACIÓN MP'!AJ16:AJ4951,"√") -> 0 | O17: TOTAL MP PROGRAMADAS IM≥12 | P17: =+GETPIVOTDATA("FRECUENCIA ANUAL DE MANTENIMIENTO",$A$49,"CRÍTICO/ RELEVANTE / IM≥12 / NO APLICA","IM ≥ 12","AÑO INGRESO A PLAN DE MANTENIMIENTO (2023 / 2024 / 2025 / 2026)",2023) -> 3 | AC17: 6
A18: N° MP EJECUTADAS IM≥12 | B18: =+COUNTIFS('CATASTRO Y PLANIFICACIÓN MP'!$O$16:$O$4951,"IM ≥ 12",'CATASTRO Y PLANIFICACIÓN MP'!Y16:Y4951,"√") -> 0 | C18: =+COUNTIFS('CATASTRO Y PLANIFICACIÓN MP'!$O$16:$O$4951,"IM ≥ 12",'CATASTRO Y PLANIFICACIÓN MP'!Z16:Z4951,"√") -> 0 | D18: =+COUNTIFS('CATASTRO Y PLANIFICACIÓN MP'!$O$16:$O$4951,"IM ≥ 12",'CATASTRO Y PLANIFICACIÓN MP'!AA16:AA4951,"√") -> 0 | E18: =+COUNTIFS('CATASTRO Y PLANIFICACIÓN MP'!$O$16:$O$4951,"IM ≥ 12",'CATASTRO Y PLANIFICACIÓN MP'!AB16:AB4951,"√") -> 0 | F18: =+COUNTIFS('CATASTRO Y PLANIFICACIÓN MP'!$O$16:$O$4951,"IM ≥ 12",'CATASTRO Y PLANIFICACIÓN MP'!AC16:AC4951,"√") -> 0 | G18: =+COUNTIFS('CATASTRO Y PLANIFICACIÓN MP'!$O$16:$O$4951,"IM ≥ 12",'CATASTRO Y PLANIFICACIÓN MP'!AD16:AD4951,"√") -> 0 | H18: =+COUNTIFS('CATASTRO Y PLANIFICACIÓN MP'!$O$16:$O$4951,"IM ≥ 12",'CATASTRO Y PLANIFICACIÓN MP'!AE16:AE4951,"√") -> 0 | I18: =+COUNTIFS('CATASTRO Y PLANIFICACIÓN MP'!$O$16:$O$4951,"IM ≥ 12",'CATASTRO Y PLANIFICACIÓN MP'!AF16:AF4951,"√") -> 0 | ... M18: =+COUNTIFS('CATASTRO Y PLANIFICACIÓN MP'!$O$16:$O$4951,"IM ≥ 12",'CATASTRO Y PLANIFICACIÓN MP'!AJ16:AJ4951,"√") -> 0 | O18: TOTAL MP EJECUTADAS EQC | P18: =+SUM(B16:M16) -> 65 | AC18: 12
A19: N° MP REPROGRAMADAS EQC | B19: =+COUNTIFS('CATASTRO Y PLANIFICACIÓN MP'!$O$16:$O$4951,"CRÍTICO",'CATASTRO Y PLANIFICACIÓN MP'!Y16:Y4951,"ꓣ") -> 0 | C19: =+COUNTIFS('CATASTRO Y PLANIFICACIÓN MP'!$O$16:$O$4951,"CRÍTICO",'CATASTRO Y PLANIFICACIÓN MP'!Z16:Z4951,"ꓣ") -> 0 | D19: =+COUNTIFS('CATASTRO Y PLANIFICACIÓN MP'!$O$16:$O$4951,"CRÍTICO",'CATASTRO Y PLANIFICACIÓN MP'!AA16:AA4951,"ꓣ") -> 0 | E19: =+COUNTIFS('CATASTRO Y PLANIFICACIÓN MP'!$O$16:$O$4951,"CRÍTICO",'CATASTRO Y PLANIFICACIÓN MP'!AB16:AB4951,"ꓣ") -> 0 | F19: =+COUNTIFS('CATASTRO Y PLANIFICACIÓN MP'!$O$16:$O$4951,"CRÍTICO",'CATASTRO Y PLANIFICACIÓN MP'!AC16:AC4951,"ꓣ") -> 0 | G19: =+COUNTIFS('CATASTRO Y PLANIFICACIÓN MP'!$O$16:$O$4951,"CRÍTICO",'CATASTRO Y PLANIFICACIÓN MP'!AD16:AD4951,"ꓣ") -> 0 | H19: =+COUNTIFS('CATASTRO Y PLANIFICACIÓN MP'!$O$16:$O$4951,"CRÍTICO",'CATASTRO Y PLANIFICACIÓN MP'!AE16:AE4951,"ꓣ") -> 0 | I19: =+COUNTIFS('CATASTRO Y PLANIFICACIÓN MP'!$O$16:$O$4951,"CRÍTICO",'CATASTRO Y PLANIFICACIÓN MP'!AF16:AF4951,"ꓣ") -> 0 | ... M19: =+COUNTIFS('CATASTRO Y PLANIFICACIÓN MP'!$O$16:$O$4951,"CRÍTICO",'CATASTRO Y PLANIFICACIÓN MP'!AJ16:AJ4951,"ꓣ") -> 0 | O19: TOTAL MP EJECUTADAS EQR | P19: =+SUM(B17:M17) -> 11 | S19: MANTENIMIENTO CORRECTIVO
A20: N° MP REPROGRAMADAS EQR | B20: =+COUNTIFS('CATASTRO Y PLANIFICACIÓN MP'!$O$16:$O$4951,"RELEVANTE",'CATASTRO Y PLANIFICACIÓN MP'!Y16:Y4951,"ꓣ") -> 0 | C20: =+COUNTIFS('CATASTRO Y PLANIFICACIÓN MP'!$O$16:$O$4951,"RELEVANTE",'CATASTRO Y PLANIFICACIÓN MP'!Z16:Z4951,"ꓣ") -> 0 | D20: =+COUNTIFS('CATASTRO Y PLANIFICACIÓN MP'!$O$16:$O$4951,"RELEVANTE",'CATASTRO Y PLANIFICACIÓN MP'!AA16:AA4951,"ꓣ") -> 0 | E20: =+COUNTIFS('CATASTRO Y PLANIFICACIÓN MP'!$O$16:$O$4951,"RELEVANTE",'CATASTRO Y PLANIFICACIÓN MP'!AB16:AB4951,"ꓣ") -> 0 | F20: =+COUNTIFS('CATASTRO Y PLANIFICACIÓN MP'!$O$16:$O$4951,"RELEVANTE",'CATASTRO Y PLANIFICACIÓN MP'!AC16:AC4951,"ꓣ") -> 0 | G20: =+COUNTIFS('CATASTRO Y PLANIFICACIÓN MP'!$O$16:$O$4951,"RELEVANTE",'CATASTRO Y PLANIFICACIÓN MP'!AD16:AD4951,"ꓣ") -> 0 | H20: =+COUNTIFS('CATASTRO Y PLANIFICACIÓN MP'!$O$16:$O$4951,"RELEVANTE",'CATASTRO Y PLANIFICACIÓN MP'!AE16:AE4951,"ꓣ") -> 0 | I20: =+COUNTIFS('CATASTRO Y PLANIFICACIÓN MP'!$O$16:$O$4951,"RELEVANTE",'CATASTRO Y PLANIFICACIÓN MP'!AF16:AF4951,"ꓣ") -> 0 | ... M20: =+COUNTIFS('CATASTRO Y PLANIFICACIÓN MP'!$O$16:$O$4951,"RELEVANTE",'CATASTRO Y PLANIFICACIÓN MP'!AJ16:AJ4951,"ꓣ") -> 0 | O20: TOTAL MP EJECUTADAS IM≥12 | P20: =+SUM(B18:M18) -> 0 | S20: ADQUISICIÓN DE REPUESTOS
A21: N° MP REPROGRAMADAS IM≥12 | B21: =+COUNTIFS('CATASTRO Y PLANIFICACIÓN MP'!$O$16:$O$4951,"IM ≥ 12",'CATASTRO Y PLANIFICACIÓN MP'!Y16:Y4951,"ꓣ") -> 0 | C21: =+COUNTIFS('CATASTRO Y PLANIFICACIÓN MP'!$O$16:$O$4951,"IM ≥ 12",'CATASTRO Y PLANIFICACIÓN MP'!Z16:Z4951,"ꓣ") -> 0 | D21: =+COUNTIFS('CATASTRO Y PLANIFICACIÓN MP'!$O$16:$O$4951,"IM ≥ 12",'CATASTRO Y PLANIFICACIÓN MP'!AA16:AA4951,"ꓣ") -> 0 | E21: =+COUNTIFS('CATASTRO Y PLANIFICACIÓN MP'!$O$16:$O$4951,"IM ≥ 12",'CATASTRO Y PLANIFICACIÓN MP'!AB16:AB4951,"ꓣ") -> 0 | F21: =+COUNTIFS('CATASTRO Y PLANIFICACIÓN MP'!$O$16:$O$4951,"IM ≥ 12",'CATASTRO Y PLANIFICACIÓN MP'!AC16:AC4951,"ꓣ") -> 0 | G21: =+COUNTIFS('CATASTRO Y PLANIFICACIÓN MP'!$O$16:$O$4951,"IM ≥ 12",'CATASTRO Y PLANIFICACIÓN MP'!AD16:AD4951,"ꓣ") -> 0 | H21: =+COUNTIFS('CATASTRO Y PLANIFICACIÓN MP'!$O$16:$O$4951,"IM ≥ 12",'CATASTRO Y PLANIFICACIÓN MP'!AE16:AE4951,"ꓣ") -> 0 | I21: =+COUNTIFS('CATASTRO Y PLANIFICACIÓN MP'!$O$16:$O$4951,"IM ≥ 12",'CATASTRO Y PLANIFICACIÓN MP'!AF16:AF4951,"ꓣ") -> 0 | ... M21: =+COUNTIFS('CATASTRO Y PLANIFICACIÓN MP'!$O$16:$O$4951,"IM ≥ 12",'CATASTRO Y PLANIFICACIÓN MP'!AJ16:AJ4951,"ꓣ") -> 0 | S21: ADQUISICIÓN DE INSUMOS
O22: INDICADOR | P22: NIVEL ALCANZADO | S22: ADQUISICION DE ACCESORIOS
O23: % EJECUCION ANUAL MP | P23: =+P13/P12 -> 7.6
A24: % EJECUCIÓN MP TOTAL MENSUAL | B24: =+IFERROR(B13/(B13+B14),"") -> 1 | C24: =+IFERROR(C13/(C13+C14),"") | D24: =+IFERROR(D13/(D13+D14),"") | E24: =+IFERROR(E13/(E13+E14),"") | F24: =+IFERROR(F13/(F13+F14),"") | G24: =+IFERROR(G13/(G13+G14),"") | H24: =+IFERROR(H13/(H13+H14),"") | I24: =+IFERROR(I13/(I13+I14),"") | ... M24: =+IFERROR(M13/(M13+M14),"") | O24: % EJECUCIÓN ANUAL EQC | P24: =+P18/P15 -> 10.833333
A25: % EJECUCIÓN MP EQC MENSUAL | B25: =+IFERROR(B16/(B16+B19),"") -> 1 | C25: =+IFERROR(C16/(C16+C19),"") | D25: =+IFERROR(D16/(D16+D19),"") | E25: =+IFERROR(E16/(E16+E19),"") | F25: =+IFERROR(F16/(F16+F19),"") | G25: =+IFERROR(G16/(G16+G19),"") | H25: =+IFERROR(H16/(H16+H19),"") | I25: =+IFERROR(I16/(I16+I19),"") | ... M25: =+IFERROR(M16/(M16+M19),"") | O25: % EJECUCIÓN ANUAL EQR | P25: =+P19/P16 -> 11
A26: % EJECUCIÓN MP EQR MENSUAL | B26: =+IFERROR(B17/(B17+B20),"") -> 1 | C26: =+IFERROR(C17/(C17+C20),"") | D26: =+IFERROR(D17/(D17+D20),"") | E26: =+IFERROR(E17/(E17+E20),"") | F26: =+IFERROR(F17/(F17+F20),"") | G26: =+IFERROR(G17/(G17+G20),"") | H26: =+IFERROR(H17/(H17+H20),"") | I26: =+IFERROR(I17/(I17+I20),"") | ... M26: =+IFERROR(M17/(M17+M20),"") | O26: % EJECUCIÓN ANUAL IM≥12 | P26: =+P20/P17 -> 0
A27: % EJECUCIÓN MP IM≥12 MENSUAL | B27: =+IFERROR(B18/(B18+B21),"") | C27: =+IFERROR(C18/(C18+C21),"") | D27: =+IFERROR(D18/(D18+D21),"") | E27: =+IFERROR(E18/(E18+E21),"") | F27: =+IFERROR(F18/(F18+F21),"") | G27: =+IFERROR(G18/(G18+G21),"") | H27: =+IFERROR(H18/(H18+H21),"") | I27: =+IFERROR(I18/(I18+I21),"") | ... M27: =+IFERROR(M18/(M18+M21),"")
A29: GASTO PROGRAMADO MP | B29: =+SUM('SEGUIMIENTO GASTO'!I8:I140) -> 705485554
A31: GASTO PROGRAMADO MC | B31: =+'CATASTRO Y PLANIFICACIÓN MP'!B13 -> 400000000
A33: EJECUCIÓN GASTO MP | B33: =+SUM('SEGUIMIENTO GASTO'!AI8:AI141) -> 97382016
A35: EJECUCIÓN GASTO MC | B35: =+SUM('SEGUIMIENTO GASTO'!AG149:AG235) -> 15588666
A37: % EJECUCIÓN DEL GASTO MP | B37: =+IFERROR(B33/B29,"") -> 0.13803545 | D37: =1-B37 -> 0.86196455
A39: % EJECUCIÓN DEL GASTO MC | B39: =+IFERROR(B35/B31,"") -> 0.038971665 | D39: =1-B39 -> 0.96102833
A42: Etiquetas de fila | B42: Suma de COSTO ANUAL DE MANTENIMIENTO SEGÚN CONVENIO / PRECIO DE REFERENCIA MANTENIMIENTO ANUAL
A43: 2023 | B43: 4650000
A44: 2024 | B44: 1250000
A45: 2025 | B45: 78000000
A46: (en blanco)
A47: Total general | B47: 83900000
A49: Etiquetas de fila | B49: Suma de FRECUENCIA ANUAL DE MANTENIMIENTO
A50: 2023 | B50: 10
A51: CRÍTICO | B51: 6
A52: IM ≥ 12 | B52: 3
A53: RELEVANTE | B53: 1
A54: 2024 | B54: 4
...
